<?xml version="1.0" ?>
<robot name="base_link" xmlns:xacro="http://www.ros.org/wiki/xacro">

<xacro:include filename="$(find base_link_description)/urdf/materials.xacro" />
<xacro:include filename="$(find base_link_description)/urdf/base_link.trans" />
<xacro:include filename="$(find base_link_description)/urdf/base_link.gazebo" />
<link name="base_link">
  <inertial>
    <origin xyz="0.0010842864645055825 1.2046052333224058e-16 -0.010284098268977257" rpy="0 0 0"/>
    <mass value="1.333544776802818"/>
    <inertia ixx="0.001792" iyy="0.005653" izz="0.006463" ixy="0.0" iyz="0.0" ixz="0.000256"/>
  </inertial>
  <visual>
    <origin xyz="0 0 0" rpy="0 0 0"/>
    <geometry>
      <mesh filename="package://base_link_description/meshes/base_link.stl" scale="0.001 0.001 0.001"/>
    </geometry>
    <material name="silver"/>
  </visual>
  <collision>
    <origin xyz="0 0 0" rpy="0 0 0"/>
    <geometry>
      <mesh filename="package://base_link_description/meshes/base_link.stl" scale="0.001 0.001 0.001"/>
    </geometry>
  </collision>
</link>

<link name="whell_2_1">
  <inertial>
    <origin xyz="4.949864740311227e-09 0.004999999999999921 4.4121930962634504e-07" rpy="0 0 0"/>
    <mass value="0.6165375582669965"/>
    <inertia ixx="0.00039" iyy="0.000771" izz="0.00039" ixy="0.0" iyz="-0.0" ixz="-0.0"/>
  </inertial>
  <visual>
    <origin xyz="0.063215 -0.055 0.019823" rpy="0 0 0"/>
    <geometry>
      <mesh filename="package://base_link_description/meshes/whell_2_1.stl" scale="0.001 0.001 0.001"/>
    </geometry>
    <material name="silver"/>
  </visual>
  <collision>
    <origin xyz="0.063215 -0.055 0.019823" rpy="0 0 0"/>
    <geometry>
      <mesh filename="package://base_link_description/meshes/whell_2_1.stl" scale="0.001 0.001 0.001"/>
    </geometry>
  </collision>
</link>

<link name="whell_1">
  <inertial>
    <origin xyz="4.94986485133353e-09 -0.004999999999999956 4.4121930961246725e-07" rpy="0 0 0"/>
    <mass value="0.6165375582669967"/>
    <inertia ixx="0.00039" iyy="0.000771" izz="0.00039" ixy="-0.0" iyz="0.0" ixz="0.0"/>
  </inertial>
  <visual>
    <origin xyz="0.063215 0.055 0.019823" rpy="0 0 0"/>
    <geometry>
      <mesh filename="package://base_link_description/meshes/whell_1.stl" scale="0.001 0.001 0.001"/>
    </geometry>
    <material name="silver"/>
  </visual>
  <collision>
    <origin xyz="0.063215 0.055 0.019823" rpy="0 0 0"/>
    <geometry>
      <mesh filename="package://base_link_description/meshes/whell_1.stl" scale="0.001 0.001 0.001"/>
    </geometry>
  </collision>
</link>

<joint name="Rev1" type="continuous">
  <origin xyz="-0.063215 0.055 -0.019823" rpy="0 0 0"/>
  <parent link="base_link"/>
  <child link="whell_2_1"/>
  <axis xyz="0.0 1.0 0.0"/>
</joint>

<joint name="Rev2" type="continuous">
  <origin xyz="-0.063215 -0.055 -0.019823" rpy="0 0 0"/>
  <parent link="base_link"/>
  <child link="whell_1"/>
  <axis xyz="0.0 -1.0 0.0"/>
</joint>

</robot>
